Workbook

Sheet Sheet1
A1: year | B1: industry | C1: employed_persons
A2: 2011 | B2: Agriculture, forestry and fishing | C2: 249828
A3: 2011 | B3: Mining | C3: 176563
A4: 2011 | B4: Manufacturing | C4: 902829
A5: 2011 | B5: Electricity, gas, water and waste services | C5: 115611
A6: 2011 | B6: Construction | C6: 828910
A7: 2011 | B7: Wholesale trade | C7: 403801
A8: 2011 | B8: Retail trade | C8: 1057310
A9: 2011 | B9: Accommodation and food services | C9: 650397
A10: 2011 | B10: Transport, postal and warehousing | C10: 479181 | E10: Row Labels | F10: Sum of employed_persons
A11: 2011 | B11: Information media and telecommunications | C11: 178190 | E11: TOTAL | F11: 32791577
A12: 2011 | B12: Financial and insurance services | C12: 377352 | E12: 2011 | F12: 10058325
A13: 2011 | B13: Rental, hiring and real estate services | C13: 158853 | E13: 2016 | F13: 10683842
A14: 2011 | B14: Professional, scientific and technical services | C14: 730062 | E14: 2021 | F14: 12049410
A15: 2011 | B15: Administrative and support services | C15: 323779 | E15: Health care and social assistance | F15: 4270366
A16: 2011 | B16: Public administration and safety | C16: 689931 | E16: 2011 | F16: 1167634
A17: 2011 | B17: Education and training | C17: 804418 | E17: 2016 | F17: 1351015
A18: 2011 | B18: Health care and social assistance | C18: 1167634 | E18: 2021 | F18: 1751717
A19: 2011 | B19: Arts and recreation services | C19: 151574 | E19: Retail trade | F19: 3210743
A20: 2011 | B20: Other services | C20: 378217 | E20: 2011 | F20: 1057310
A21: 2011 | B21: Inadequately described/Not stated | C21: 233885 | E21: 2016 | F21: 1053816
A22: 2011 | B22: TOTAL | C22: 10058325 | E22: 2021 | F22: 1099617
A23: 2016 | B23: Agriculture, Forestry and Fishing | C23: 266946 | E23: Construction | F23: 2807611
A24: 2016 | B24: Mining | C24: 177647 | E24: 2011 | F24: 828910
A25: 2016 | B25: Manufacturing | C25: 683688 | E25: 2016 | F25: 911056
A26: 2016 | B26: Electricity, Gas, Water and Waste Services | C26: 115753 | E26: 2021 | F26: 1067645
A27: 2016 | B27: Construction | C27: 911056 | E27: Education and training | F27: 2791633
A28: 2016 | B28: Wholesale Trade | C28: 307741 | E28: 2011 | F28: 804418
A29: 2016 | B29: Retail Trade | C29: 1053816 | E29: 2016 | F29: 925895
A30: 2016 | B30: Accommodation and Food Services | C30: 738231 | E30: 2021 | F30: 1061320
A31: 2016 | B31: Transport, Postal and Warehousing | C31: 499491 | E31: Professional, scientific and technical services | F31: 2451134
A32: 2016 | B32: Information Media and Telecommunications | C32: 179521 | E32: 2011 | F32: 730062
A33: 2016 | B33: Financial and Insurance Services | C33: 384608 | E33: 2016 | F33: 775978
A34: 2016 | B34: Rental, Hiring and Real Estate Services | C34: 182151 | E34: 2021 | F34: 945094
A35: 2016 | B35: Professional, Scientific and Technical Services | C35: 775978 | E35: Manufacturing | F35: 2301276
A36: 2016 | B36: Administrative and Support Services | C36: 365731 | E36: 2011 | F36: 902829
A37: 2016 | B37: Public Administration and Safety | C37: 713135 | E37: 2016 | F37: 683688
A38: 2016 | B38: Education and Training | C38: 925895 | E38: 2021 | F38: 714759
A39: 2016 | B39: Health Care and Social Assistance | C39: 1351015 | E39: Accommodation and food services | F39: 2172365
A40: 2016 | B40: Arts and Recreation Services | C40: 176667 | E40: 2011 | F40: 650397
...

Sheet Sheet2
A1: year | B1: industry | C1: employed_persons
A2: 2011 | B2: Manufacturing | C2: 902829
A3: 2011 | B3: Construction | C3: 828910
A4: 2011 | B4: Retail trade | C4: 1057310
A5: 2011 | B5: Transport, postal and warehousing | C5: 479181
A6: 2011 | B6: Professional, scientific and technical services | C6: 730062
A7: 2011 | B7: Education and training | C7: 804418
A8: 2011 | B8: Health care and social assistance | C8: 1167634
A9: 2011 | B9: Accommodation and food services | C9: 650397
A10: 2016 | B10: Manufacturing | C10: 683688
A11: 2016 | B11: Construction | C11: 911056
A12: 2016 | B12: Retail trade | C12: 1053816
A13: 2016 | B13: Transport, postal and warehousing | C13: 499491
... A25: 2021 | B25: Accommodation and food services | C25: 783737

Sheet Sheet3
A1: year | B1: industry | C1: employed_persons
A2: 2011 | B2: Manufacturing | C2: 902829 | D2: =C2/(Sheet1!$C$22-Sheet1!$C$21) -> 0.09189623 | E2: =D2*100 -> 9.189623
A3: 2011 | B3: Construction | C3: 828910 | D3: =C3/(Sheet1!$C$22-Sheet1!$C$21) -> 0.084372239 | E3: =D3*100 -> 8.4372239
A4: 2011 | B4: Retail trade | C4: 1057310 | D4: =C4/(Sheet1!$C$22-Sheet1!$C$21) -> 0.10762038 | E4: =D4*100 -> 10.762038
A5: 2011 | B5: Transport, postal and warehousing | C5: 479181 | D5: =C5/(Sheet1!$C$22-Sheet1!$C$21) -> 0.048774383 | E5: =D5*100 -> 4.8774383
A6: 2011 | B6: Professional, scientific and technical services | C6: 730062 | D6: =C6/(Sheet1!$C$22-Sheet1!$C$21) -> 0.0743108 | E6: =D6*100 -> 7.43108
A7: 2011 | B7: Education and training | C7: 804418 | D7: =C7/(Sheet1!$C$22-Sheet1!$C$21) -> 0.081879273 | E7: =D7*100 -> 8.1879273
A8: 2011 | B8: Health care and social assistance | C8: 1167634 | D8: =C8/(Sheet1!$C$22-Sheet1!$C$21) -> 0.11884993 | E8: =D8*100 -> 11.884993
A9: 2011 | B9: Accommodation and food services | C9: 650397 | D9: =C9/(Sheet1!$C$22-Sheet1!$C$21) -> 0.066201941 | E9: =D9*100 -> 6.6201941
A10: 2016 | B10: Manufacturing | C10: 683688 | D10: =C10/(Sheet1!$C$43-Sheet1!$C$42) -> 0.066971119 | E10: =D10*100 -> 6.6971119
A11: 2016 | B11: Construction | C11: 911056 | D11: =C11/(Sheet1!$C$43-Sheet1!$C$42) -> 0.089243105 | E11: =D11*100 -> 8.9243105
A12: 2016 | B12: Retail trade | C12: 1053816 | D12: =C12/(Sheet1!$C$43-Sheet1!$C$42) -> 0.10322726 | E12: =D12*100 -> 10.322726
A13: 2016 | B13: Transport, postal and warehousing | C13: 499491 | D13: =C13/(Sheet1!$C$43-Sheet1!$C$42) -> 0.048927978 | E13: =D13*100 -> 4.8927978
A14: 2016 | B14: Professional, scientific and technical services | C14: 775978 | D14: =C14/(Sheet1!$C$43-Sheet1!$C$42) -> 0.076011449 | E14: =D14*100 -> 7.6011449
A15: 2016 | B15: Education and training | C15: 925895 | D15: =C15/(Sheet1!$C$43-Sheet1!$C$42) -> 0.09069667 | E15: =D15*100 -> 9.069667
A16: 2016 | B16: Health care and social assistance | C16: 1351015 | D16: =C16/(Sheet1!$C$43-Sheet1!$C$42) -> 0.13233959 | E16: =D16*100 -> 13.233959
A17: 2016 | B17: Accommodation and food services | C17: 738231 | D17: =C17/(Sheet1!$C$43-Sheet1!$C$42) -> 0.072313916 | E17: =D17*100 -> 7.2313916
A18: 2021 | B18: Manufacturing | C18: 714759 | D18: =C18/(Sheet1!$C$64-Sheet1!$C$63) -> 0.062031709 | E18: =D18*100 -> 6.2031709
A19: 2021 | B19: Construction | C19: 1067645 | D19: =C19/(Sheet1!$C$64-Sheet1!$C$63) -> 0.092657586 | E19: =D19*100 -> 9.2657586
A20: 2021 | B20: Retail trade | C20: 1099617 | D20: =C20/(Sheet1!$C$64-Sheet1!$C$63) -> 0.095432337 | E20: =D20*100 -> 9.5432337
A21: 2021 | B21: Transport, postal and warehousing | C21: 546364 | D21: =C21/(Sheet1!$C$64-Sheet1!$C$63) -> 0.047417231 | E21: =D21*100 -> 4.7417231
A22: 2021 | B22: Professional, scientific and technical services | C22: 945094 | D22: =C22/(Sheet1!$C$64-Sheet1!$C$63) -> 0.082021766 | E22: =D22*100 -> 8.2021766
A23: 2021 | B23: Education and training | C23: 1061320 | D23: =C23/(Sheet1!$C$64-Sheet1!$C$63) -> 0.092108659 | E23: =D23*100 -> 9.2108659
A24: 2021 | B24: Health care and social assistance | C24: 1751717 | D24: =C24/(Sheet1!$C$64-Sheet1!$C$63) -> 0.15202607 | E24: =D24*100 -> 15.202607
A25: 2021 | B25: Accommodation and food services | C25: 783737 | D25: =C25/(Sheet1!$C$64-Sheet1!$C$63) -> 0.068018095 | E25: =D25*100 -> 6.8018095

Sheet Sheet4
A1: year | B1: industry | C1: employed_persons
A2: 2011 | B2: Manufacturing | C2: 8.9759378 | F2: 9.189623
A3: 2011 | B3: Construction | C3: 8.2410342 | F3: 8.4372239
A4: 2011 | B4: Retail trade | C4: 10.51179 | F4: 10.762038
A5: 2011 | B5: Transport, postal and warehousing | C5: 4.7640238 | F5: 4.8774383
A6: 2011 | B6: Professional, scientific and technical services | C6: 7.258286 | F6: 7.43108
A7: 2011 | B7: Education and training | C7: 7.9975344 | F7: 8.1879273
A8: 2011 | B8: Health care and social assistance | C8: 11.608633 | F8: 11.884993
A9: 2011 | B9: Accommodation and food services | C9: 6.4662556 | F9: 6.6201941
A10: 2016 | B10: Manufacturing | C10: 6.399271 | F10: 6.6971119
A11: 2016 | B11: Construction | C11: 8.5274193 | F11: 8.9243105
A12: 2016 | B12: Retail trade | C12: 9.8636427 | F12: 10.322726
A13: 2016 | B13: Transport, postal and warehousing | C13: 4.6752002 | F13: 4.8927978
... A25: 2021 | B25: Accommodation and food services | C25: 6.50436 | F25: 6.8018095
